Workbook

Sheet الصفحة الرئيسية

Sheet الرسوم البيانية
A2: المنظمة | B2: ألعدد
A3: qa | B3: 2654
A4: qw | B4: 4856
A5: qs | B5: 5861
A6: qe | B6: 1235
A7: qf | B7: 1564
A8: we | B8: 8945
A9: sd | B9: 5644
A10: fd | B10: 5465
A11: er | B11: 879
A12: gf | B12: 8978
A13: rt | B13: 5847
A14: fd | B14: 4123
A15: fgs | B15: 3214

Sheet البحث
E1: البحث السريع | F1: {=_xlfn._xlws.FILTER('بيانات المتدربين'!K:K,ISNUMBER(SEARCH(البحث!E3,'بيانات المتدربين'!K:K)),"NO DATA")} -> بشر لؤي المصري - HR-2016 - 2013/07/15 - 3017 - 2015
E3: بشر
A4: Row Labels | B4: Sum of عام التعيين
A5: إياد فؤاد السعدي
A6: LEG-4021 | B6: 2019 | E6: 4019
A7: باسل أكرم السعيد | E7: =VLOOKUP(E6,'بيانات المتدربين'!A:E,5,FALSE) -> دينا نبيل بركات
A8: HR-2014 | B8: 2012 | E8: =VLOOKUP(E6,'المعاملات المالية'!A:G,7,FALSE) -> 129.15
A9: باسم صبحي عيسى | E9: ="القسم :" & VLOOKUP(E6,'بيانات المتدربين'!A:H,8,FALSE) -> القسم :LEG
A10: ADM-3013 | B10: 2014
A11: بانة مجد حرب
A12: FIN-1001 | B12: 2010
A13: بشار مؤيد جود
A14: HR-2015 | B14: 2014
A15: بشر لؤي المصري
A16: HR-2016 | B16: 2013
A17: تامر جلال عوض
A18: ADM-3021 | B18: 2016
A19: تامر شادي الشريف
A20: LEG-4026 | B20: 2019
A21: جنى راشد العطار
A22: HR-2011 | B22: 2013
A23: حمزة عياش المحمد
A24: HR-2013 | B24: 2014
A25: خالد عمر المصري
A26: FIN-1002 | B26: 2009
A27: خلود صائب بكر
A28: ADM-3018 | B28: 2017
A29: دينا نبيل بركات
A30: LEG-4019 | B30: 2019
A31: رامي غياث طعمة
A32: LEG-4024 | B32: 2018
A33: رشا عبد الله صقر
A34: LEG-4017 | B34: 2019
A35: رغد عدنان حمد
A36: LEG-4018 | B36: 2017
A37: زياد مطيع العبود
A38: ADM-3012 | B38: 2016
A39: سامر وليد الخطيب
A40: ADM-3010 | B40: 2015
A41: سحر ماجد القاضي
...

Sheet بيانات المتدربين
A1: الكود الوظيفي | B1: الاسم الثالث | C1: الاسم الثاني | D1: الاسم الأول | E1: تنظيف البيانات | F1: الجنس | G1: الرقم الوظيفي-القسم | H1: القسم | I1: عام التعيين | J1: تاريخ التعيين | K1: ألمعلومات الكاملة
A2: 4021 | B2: السعدي | C2: فؤاد | D2: إياد | E2: إياد فؤاد السعدي | F2: ذكر | G2: LEG-4021 | H2: LEG | I2: 2019 | J2: 2019/10/05 | K2: =_xlfn.TEXTJOIN(" - ",TRUE,E2,G2,J2,'بيانات المتدربين'!$A29,'بيانات المتدربين'!$I29) -> إياد فؤاد السعدي - LEG-4021 - 2019/10/05 - 4025 - 2020
A3: 2014 | B3: السعيد | C3: أكرم | D3: باسل | E3: باسل أكرم السعيد | F3: ذكر | G3: HR-2014 | H3: HR | I3: 2012 | J3: 2012/10/22 | K3: =_xlfn.TEXTJOIN(" - ",TRUE,E3,G3,J3,'بيانات المتدربين'!$A39,'بيانات المتدربين'!$I39) -> باسل أكرم السعيد - HR-2014 - 2012/10/22 - 2006 - 2011
A4: 3013 | B4: عيسى | C4: صبحي | D4: باسم | E4: باسم صبحي عيسى | F4: ذكر | G4: ADM-3013 | H4: ADM | I4: 2014 | J4: 2014/05/15 | K4: =_xlfn.TEXTJOIN(" - ",TRUE,E4,G4,J4,'بيانات المتدربين'!$A16,'بيانات المتدربين'!$I16) -> باسم صبحي عيسى - ADM-3013 - 2014/05/15 - 4017 - 2010
A5: 1001 | B5: العلي | C5: محمد | D5: أحمد | E5: بانة مجد حرب | F5: أنثى | G5: FIN-1001 | H5: FIN | I5: 2010 | J5: 41771 | K5: =_xlfn.TEXTJOIN(" - ",TRUE,E5,G5,J5,'بيانات المتدربين'!$A2,'بيانات المتدربين'!$I2) -> بانة مجد حرب - FIN-1001 - 41771 - 4021 - 2019
A6: 2015 | B6: جود | C6: مؤيد | D6: بشار | E6: بشار مؤيد جود | F6: ذكر | G6: HR-2015 | H6: HR | I6: 2014 | J6: 2014/01/25 | K6: =_xlfn.TEXTJOIN(" - ",TRUE,E6,G6,J6,'بيانات المتدربين'!$A43,'بيانات المتدربين'!$I43) -> بشار مؤيد جود - HR-2015 - 2014/01/25 - 3019 - 2015
A7: 2016 | B7: المصري | C7: لؤي | D7: بشر | E7: بشر لؤي المصري | F7: ذكر | G7: HR-2016 | H7: HR | I7: 2013 | J7: 2013/07/15 | K7: =_xlfn.TEXTJOIN(" - ",TRUE,E7,G7,J7,'بيانات المتدربين'!$A47,'بيانات المتدربين'!$I47) -> بشر لؤي المصري - HR-2016 - 2013/07/15 - 3017 - 2015
A8: 3021 | B8: عوض | C8: جلال | D8: رانية | E8: تامر جلال عوض | F8: ذكر | G8: ADM-3021 | H8: ADM | I8: 2016 | J8: 2016/11/30 | K8: =_xlfn.TEXTJOIN(" - ",TRUE,E8,G8,J8,'بيانات المتدربين'!$A48,'بيانات المتدربين'!$I48) -> تامر جلال عوض - ADM-3021 - 2016/11/30 - 1005 - 2010
A9: 4026 | B9: الشريف | C9: شادي | D9: تامر | E9: تامر شادي الشريف | F9: ذكر | G9: LEG-4026 | H9: LEG | I9: 2019 | J9: 2019/04/10 | K9: =_xlfn.TEXTJOIN(" - ",TRUE,E9,G9,J9,'بيانات المتدربين'!$A49,'بيانات المتدربين'!$I49) -> تامر شادي الشريف - LEG-4026 - 2019/04/10 - 1006 - 2007
A10: 3013 | B10: العطار | C10: راشد | D10: جنى | E10: جنى راشد العطار | F10: أنثى | G10: HR-2011 | H10: ADM | I10: 2013 | J10: 2013/09/20 | K10: =_xlfn.TEXTJOIN(" - ",TRUE,E10,G10,J10,'بيانات المتدربين'!$A27,'بيانات المتدربين'!$I27) -> جنى راشد العطار - HR-2011 - 2013/09/20 - 1013 - 2008
A11: 2013 | B11: المحمد | C11: عياش | D11: حمزة | E11: حمزة عياش المحمد | F11: ذكر | G11: HR-2013 | H11: HR | I11: 2014 | J11: 2014/07/20 | K11: =_xlfn.TEXTJOIN(" - ",TRUE,E11,G11,J11,'بيانات المتدربين'!$A35,'بيانات المتدربين'!$I35) -> حمزة عياش المحمد - HR-2013 - 2014/07/20 - 1009 - 2011
A12: 1002 | B12: المصري | C12: عمر | D12: خالد | E12: خالد عمر المصري | F12: ذكر | G12: FIN-1002 | H12: FIN | I12: 2009 | J12: 2009/01/25 | K12: =_xlfn.TEXTJOIN(" - ",TRUE,E12,G12,J12,'بيانات المتدربين'!$A6,'بيانات المتدربين'!$I6) -> خالد عمر المصري - FIN-1002 - 2009/01/25 - 2015 - 2014
A13: 3018 | B13: بكر | C13: صائب | D13: خلود | E13: خلود صائب بكر | F13: أنثى | G13: ADM-3018 | H13: ADM | I13: 2017 | J13: 2017/11/10 | K13: =_xlfn.TEXTJOIN(" - ",TRUE,E13,G13,J13,'بيانات المتدربين'!$A36,'بيانات المتدربين'!$I36) -> خلود صائب بكر - ADM-3018 - 2017/11/10 - 4015 - 2011
A14: 4019 | B14: بركات | C14: نبيل | D14: دينا | E14: دينا نبيل بركات | F14: أنثى | G14: LEG-4019 | H14: LEG | I14: 2019 | J14: 2019/01/15 | K14: =_xlfn.TEXTJOIN(" - ",TRUE,E14,G14,J14,'بيانات المتدربين'!$A21,'بيانات المتدربين'!$I21) -> دينا نبيل بركات - LEG-4019 - 2019/01/15 - 2010 - 2011
A15: 4024 | B15: طعمة | C15: غياث | D15: رامي | E15: رامي غياث طعمة | F15: ذكر | G15: LEG-4024 | H15: LEG | I15: 2018 | J15: 2018/03/30 | K15: =_xlfn.TEXTJOIN(" - ",TRUE,E15,G15,J15,'بيانات المتدربين'!$A41,'بيانات المتدربين'!$I41) -> رامي غياث طعمة - LEG-4024 - 2018/03/30 - 2008 - 2011
A16: 4017 | B16: صقر | C16: الله | D16: رشا | E16: رشا عبد الله صقر | F16: أنثى | G16: LEG-4017 | H16: LEG | I16: 2010 | J16: 2019/06/25 | K16: =_xlfn.TEXTJOIN(" - ",TRUE,E16,G16,J16,'بيانات المتدربين'!$A13,'بيانات المتدربين'!$I13) -> رشا عبد الله صقر - LEG-4017 - 2019/06/25 - 3018 - 2017
A17: 4018 | B17: حمد | C17: عدنان | D17: رغد | E17: رغد عدنان حمد | F17: أنثى | G17: LEG-4018 | H17: FIN | I17: 2017 | J17: 2017/08/20 | K17: =_xlfn.TEXTJOIN(" - ",TRUE,E17,G17,J17,'بيانات المتدربين'!$A17,'بيانات المتدربين'!$I17) -> رغد عدنان حمد - LEG-4018 - 2017/08/20 - 4018 - 2017
A18: 3012 | B18: العبود | C18: مطيع | D18: زياد | E18: زياد مطيع العبود | F18: ذكر | G18: ADM-3012 | H18: ADM | I18: 2010 | J18: 2016/10/18 | K18: =_xlfn.TEXTJOIN(" - ",TRUE,E18,G18,J18,'بيانات المتدربين'!$A12,'بيانات المتدربين'!$I12) -> زياد مطيع العبود - ADM-3012 - 2016/10/18 - 1002 - 2009
A19: 3010 | B19: الخطيب | C19: وليد | D19: سامر | E19: سامر وليد الخطيب | F19: ذكر | G19: ADM-3010 | H19: ADM | I19: 2012 | J19: 2015/03/15 | K19: =_xlfn.TEXTJOIN(" - ",TRUE,E19,G19,J19,'بيانات المتدربين'!$A4,'بيانات المتدربين'!$I4) -> سامر وليد الخطيب - ADM-3010 - 2015/03/15 - 3013 - 2014
A20: 2009 | B20: القاضي | C20: ماجد | D20: سحر | E20: سحر ماجد القاضي | F20: أنثى | G20: HR-2009 | H20: HR | I20: 2013 | J20: 2013/05/10 | K20: =_xlfn.TEXTJOIN(" - ",TRUE,E20,G20,J20,'بيانات المتدربين'!$A19,'بيانات المتدربين'!$I19) -> سحر ماجد القاضي - HR-2009 - 2013/05/10 - 3010 - 2012
A21: 2010 | B21: الحكيم | C21: بشار | D21: سلمى | E21: سلمى بشار الحكيم | F21: أنثى | G21: HR-2010 | H21: HR | I21: 2011 | J21: 2011/02/28 | K21: =_xlfn.TEXTJOIN(" - ",TRUE,E21,G21,J21,'بيانات المتدربين'!$A23,'بيانات المتدربين'!$I23) -> سلمى بشار الحكيم - HR-2010 - 2011/02/28 - 3012 - 2017
A22: 1011 | B22: السيد | C22: ممدوح | D22: سلوى | E22: سلوى ممدوح السيد | F22: أنثى | G22: FIN-1011 | H22: FIN | I22: 2011 | J22: 2011/08/10 | K22: =_xlfn.TEXTJOIN(" - ",TRUE,E22,G22,J22,'بيانات المتدربين'!$A42,'بيانات المتدربين'!$I42) -> سلوى ممدوح السيد - FIN-1011 - 2011/08/10 - 1010 - 2009
A23: 3012 | B23: الرفاعي | C23: عصمت | D23: صفاء | E23: صفاء عصمت الرفاعي | F23: أنثى | G23: ADM-3012 | H23: ADM | I23: 2017 | J23: 2017/06/14 | K23: =_xlfn.TEXTJOIN(" - ",TRUE,E23,G23,J23,'بيانات المتدربين'!$A44,'بيانات المتدربين'!$I44) -> صفاء عصمت الرفاعي - ADM-3012 - 2017/06/14 - 1008 - 2008
A24: 1004 | B24: الخوري | C24: منير | D24: طارق | E24: طارق منير الخوري | F24: ذكر | G24: FIN-1004 | H24: FIN | I24: 2008 | J24: 2008/03/12 | K24: =_xlfn.TEXTJOIN(" - ",TRUE,E24,G24,J24,'بيانات المتدربين'!$A14,'بيانات المتدربين'!$I14) -> طارق منير الخوري - FIN-1004 - 2008/03/12 - 4019 - 2019
A25: 4022 | B25: فوزي | C25: أسامة | D25: طلال | E25: طلال أسامة فوزي | F25: ذكر | G25: LEG-4022 | H25: LEG | I25: 2018 | J25: 2018/08/14 | K25: =_xlfn.TEXTJOIN(" - ",TRUE,E25,G25,J25,'بيانات المتدربين'!$A33,'بيانات المتدربين'!$I33) -> طلال أسامة فوزي - LEG-4022 - 2018/08/14 - 2012 - 2012
A26: 4020 | B26: الدين | C26: سيف | D26: عبير | E26: عبير سيف الدين | F26: أنثى | G26: LEG-4020 | H26: LEG | I26: 2017 | J26: 2017/12/01 | K26: =_xlfn.TEXTJOIN(" - ",TRUE,E26,G26,J26,'بيانات المتدربين'!$A25,'بيانات المتدربين'!$I25) -> عبير سيف الدين - LEG-4020 - 2017/12/01 - 4022 - 2018
A27: 1013 | B27: بيك | C27: خيري | D27: عزة | E27: عزة خيري بيك | F27: أنثى | G27: FIN-1013 | H27: FIN | I27: 2008 | J27: 2008/09/05 | K27: =_xlfn.TEXTJOIN(" - ",TRUE,E27,G27,J27,'بيانات المتدربين'!$A50,'بيانات المتدربين'!$I50) -> عزة خيري بيك - FIN-1013 - 2008/09/05 - 3011 - 2014
A28: 4023 | B28: عثمان | C28: رشيد | D28: عصام | E28: عصام رشيد عثمان | F28: ذكر | G28: LEG-4023 | H28: LEG | I28: 2020 | J28: 2020/02/05 | K28: =_xlfn.TEXTJOIN(" - ",TRUE,E28,G28,J28,'بيانات المتدربين'!$A37,'بيانات المتدربين'!$I37) -> عصام رشيد عثمان - LEG-4023 - 2020/02/05 - 3016 - 2016
A29: 4025 | B29: حمود | C29: تيسير | D29: علاء | E29: علاء تيسير حمود | F29: ذكر | G29: LEG-4025 | H29: LEG | I29: 2020 | J29: 2020/09/01 | K29: =_xlfn.TEXTJOIN(" - ",TRUE,E29,G29,J29,'بيانات المتدربين'!$A45,'بيانات المتدربين'!$I45) -> علاء تيسير حمود - LEG-4025 - 2020/09/01 - 4016 - 2017
A30: 3014 | B30: الصالح | C30: زهير | D30: عمار | E30: عمار زهير الصالح | F30: ذكر | G30: ADM-3014 | H30: ADM | I30: 2016 | J30: 2016/09/05 | K30: =_xlfn.TEXTJOIN(" - ",TRUE,E30,G30,J30,'بيانات المتدربين'!$A20,'بيانات المتدربين'!$I20) -> عمار زهير الصالح - ADM-3014 - 2016/09/05 - 2009 - 2013
A31: 3015 | B31: سلامة | C31: مروان | D31: فادي | E31: فادي مروان سلامة | F31: ذكر | G31: ADM-3015 | H31: ADM | I31: 2014 | J31: 2014/08/14 | K31: =_xlfn.TEXTJOIN(" - ",TRUE,E31,G31,J31,'بيانات المتدربين'!$A24,'بيانات المتدربين'!$I24) -> فادي مروان سلامة - ADM-3015 - 2014/08/14 - 1004 - 2008
A32: 2005 | B32: الحسن | C32: محمود | D32: فاطمة | E32: فاطمة محمود الحسن | F32: أنثى | G32: HR-2005 | H32: ADM | I32: 2012 | J32: 2012/08/20 | K32: =_xlfn.TEXTJOIN(" - ",TRUE,E32,G32,J32,'بيانات المتدربين'!$A3,'بيانات المتدربين'!$I3) -> فاطمة محمود الحسن - HR-2005 - 2012/08/20 - 2014 - 2012
A33: 2012 | B33: العمر | C33: تميم | D33: فراس | E33: فراس تميم العمر | F33: ذكر | G33: HR-2012 | H33: HR | I33: 2012 | J33: 2012/01/30 | K33: =_xlfn.TEXTJOIN(" - ",TRUE,E33,G33,J33,'بيانات المتدربين'!$A31,'بيانات المتدربين'!$I31) -> فراس تميم العمر - HR-2012 - 2012/01/30 - 3015 - 2014
A34: 1007 | B34: الراوي | C34: حاتم | D34: قيس | E34: قيس حاتم الراوي | F34: ذكر | G34: FIN-1007 | H34: FIN | I34: 2010 | J34: 2010/06/15 | K34: =_xlfn.TEXTJOIN(" - ",TRUE,E34,G34,J34,'بيانات المتدربين'!$A26,'بيانات المتدربين'!$I26) -> قيس حاتم الراوي - FIN-1007 - 2010/06/15 - 4020 - 2017
A35: 1009 | B35: الشعلان | C35: نوري | D35: لمى | E35: لمى نوري الشعلان | F35: أنثى | G35: FIN-1009 | H35: FIN | I35: 2011 | J35: 2011/03/15 | K35: =_xlfn.TEXTJOIN(" - ",TRUE,E35,G35,J35,'بيانات المتدربين'!$A34,'بيانات المتدربين'!$I34) -> لمى نوري الشعلان - FIN-1009 - 2011/03/15 - 1007 - 2010
A36: 4015 | B36: يوسف | C36: الرحمن | D36: ليلى | E36: ليلى عبد الرحمن يوسف | F36: أنثى | G36: LEG-4015 | H36: LEG | I36: 2011 | J36: 2018/11/02 | K36: =_xlfn.TEXTJOIN(" - ",TRUE,E36,G36,J36,'بيانات المتدربين'!$A5,'بيانات المتدربين'!$I5) -> ليلى عبد الرحمن يوسف - LEG-4015 - 2018/11/02 - 1001 - 2010
A37: 3016 | B37: شاهين | C37: وفيق | D37: مازن | E37: مازن وفيق شاهين | F37: ذكر | G37: ADM-3016 | H37: ADM | I37: 2016 | J37: 2016/04/10 | K37: =_xlfn.TEXTJOIN(" - ",TRUE,E37,G37,J37,'بيانات المتدربين'!$A28,'بيانات المتدربين'!$I28) -> مازن وفيق شاهين - ADM-3016 - 2016/04/10 - 4023 - 2020
A38: 1012 | B38: الناصر | C38: يونس | D38: مروة | E38: مروة يونس الناصر | F38: أنثى | G38: FIN-1012 | H38: FIN | I38: 2010 | J38: 2010/02/20 | K38: =_xlfn.TEXTJOIN(" - ",TRUE,E38,G38,J38,'بيانات المتدربين'!$A46,'بيانات المتدربين'!$I46) -> مروة يونس الناصر - FIN-1012 - 2010/02/20 - 2007 - 2010
A39: 2006 | B39: الدالي | C39: إبراهيم | D39: مريم | E39: مريم إبراهيم الدالي | F39: أنثى | G39: HR-2006 | H39: HR | I39: 2011 | J39: 2011/07/14 | K39: =_xlfn.TEXTJOIN(" - ",TRUE,E39,G39,J39,'بيانات المتدربين'!$A7,'بيانات المتدربين'!$I7) -> مريم إبراهيم الدالي - HR-2006 - 2011/07/14 - 2016 - 2013
A40: 1003 | B40: الزين | C40: كمال | D40: مصطفى | E40: مصطفى كمال الزين | F40: ذكر | G40: FIN-1003 | H40: FIN | I40: 2010 | J40: 2010/09/10 | K40: =_xlfn.TEXTJOIN(" - ",TRUE,E40,G40,J40,'بيانات المتدربين'!$A10,'بيانات المتدربين'!$I10) -> مصطفى كمال الزين - FIN-1003 - 2010/09/10 - 3013 - 2013
...

Sheet المعاملات المالية
A1: ألرقم الوظيفي | B1: أسماء الموظفين | C1: تاريخ التعيين | D1: سنوات العمل | E1: الراتب | F1: زيادة الراتب | G1: الراتب الكامل | H1: الفئة الوظيفية | I1: التعويضات | J1: الحالة | K1: Column3
A2: =Table4[[#This Row],[الكود الوظيفي]] -> 4021 | B2: ='بيانات المتدربين'!$E2 -> إياد فؤاد السعدي | C2: ='بيانات المتدربين'!$J2 -> 2019/10/05 | D2: =DATEDIF(C2,TODAY(),"Y") -> 6 | E2: 90 | F2: =IF(D2>=15,E2*20%,IF(D2>=10,E2*15%,IF(D2>=5,E2*10%))) -> 9 | G2: =SUM(E2+F2) -> 99 | H2: S | I2: =IF(H2="M",F2*12%,IF(H2="S",F2*4%,IF(H2="R",F2*2%)))+G2 -> 99.36 | J2: =IF(OR(E2>100,D2>15),"متقاعد","قيد العمل") -> قيد العمل
A3: =Table4[[#This Row],[الكود الوظيفي]] -> 2014 | B3: ='بيانات المتدربين'!$E3 -> باسل أكرم السعيد | C3: ='بيانات المتدربين'!$J3 -> 2012/10/22 | D3: =DATEDIF(C3,TODAY(),"Y") -> 13 | E3: 100 | F3: =IF(D3>=15,E3*20%,IF(D3>=10,E3*15%,IF(D3>=5,E3*10%))) -> 15 | G3: =SUM(E3+F3) -> 115 | H3: M | I3: =IF(H3="M",F3*12%,IF(H3="S",F3*4%,IF(H3="R",F3*2%)))+G3 -> 116.8 | J3: =IF(OR(E3>100,D3>15),"متقاعد","قيد العمل") -> قيد العمل
A4: =Table4[[#This Row],[الكود الوظيفي]] -> 3013 | B4: ='بيانات المتدربين'!$E4 -> باسم صبحي عيسى | C4: ='بيانات المتدربين'!$J4 -> 2014/05/15 | D4: =DATEDIF(C4,TODAY(),"Y") -> 11 | E4: 100 | F4: =IF(D4>=15,E4*20%,IF(D4>=10,E4*15%,IF(D4>=5,E4*10%))) -> 15 | G4: =SUM(E4+F4) -> 115 | H4: S | I4: =IF(H4="M",F4*12%,IF(H4="S",F4*4%,IF(H4="R",F4*2%)))+G4 -> 115.6 | J4: =IF(OR(E4>100,D4>15),"متقاعد","قيد العمل") -> قيد العمل
A5: =Table4[[#This Row],[الكود الوظيفي]] -> 1001 | B5: ='بيانات المتدربين'!$E5 -> بانة مجد حرب | C5: ='بيانات المتدربين'!$J5 -> 41771 | D5: =DATEDIF(C5,TODAY(),"Y") -> 11 | E5: 260 | F5: =IF(D5>=15,E5*20%,IF(D5>=10,E5*15%,IF(D5>=5,E5*10%))) -> 39 | G5: =SUM(E5+F5) -> 299 | H5: M | I5: =IF(H5="M",F5*12%,IF(H5="S",F5*4%,IF(H5="R",F5*2%)))+G5 -> 303.68 | J5: =IF(OR(E5>100,D5>15),"متقاعد","قيد العمل") -> متقاعد
A6: =Table4[[#This Row],[الكود الوظيفي]] -> 2015 | B6: ='بيانات المتدربين'!$E6 -> بشار مؤيد جود | C6: ='بيانات المتدربين'!$J6 -> 2014/01/25 | D6: =DATEDIF(C6,TODAY(),"Y") -> 12 | E6: 100 | F6: =IF(D6>=15,E6*20%,IF(D6>=10,E6*15%,IF(D6>=5,E6*10%))) -> 15 | G6: =SUM(E6+F6) -> 115 | H6: M | I6: =IF(H6="M",F6*12%,IF(H6="S",F6*4%,IF(H6="R",F6*2%)))+G6 -> 116.8 | J6: =IF(OR(E6>100,D6>15),"متقاعد","قيد العمل") -> قيد العمل
A7: =Table4[[#This Row],[الكود الوظيفي]] -> 2016 | B7: ='بيانات المتدربين'!$E7 -> بشر لؤي المصري | C7: ='بيانات المتدربين'!$J7 -> 2013/07/15 | D7: =DATEDIF(C7,TODAY(),"Y") -> 12 | E7: 100 | F7: =IF(D7>=15,E7*20%,IF(D7>=10,E7*15%,IF(D7>=5,E7*10%))) -> 15 | G7: =SUM(E7+F7) -> 115 | H7: M | I7: =IF(H7="M",F7*12%,IF(H7="S",F7*4%,IF(H7="R",F7*2%)))+G7 -> 116.8 | J7: =IF(OR(E7>100,D7>15),"متقاعد","قيد العمل") -> قيد العمل
A8: =Table4[[#This Row],[الكود الوظيفي]] -> 3021 | B8: ='بيانات المتدربين'!$E8 -> تامر جلال عوض | C8: ='بيانات المتدربين'!$J8 -> 2016/11/30 | D8: =DATEDIF(C8,TODAY(),"Y") -> 9 | E8: 100 | F8: =IF(D8>=15,E8*20%,IF(D8>=10,E8*15%,IF(D8>=5,E8*10%))) -> 10 | G8: =SUM(E8+F8) -> 110 | H8: S | I8: =IF(H8="M",F8*12%,IF(H8="S",F8*4%,IF(H8="R",F8*2%)))+G8 -> 110.4 | J8: =IF(OR(E8>100,D8>15),"متقاعد","قيد العمل") -> قيد العمل
A9: =Table4[[#This Row],[الكود الوظيفي]] -> 4026 | B9: ='بيانات المتدربين'!$E9 -> تامر شادي الشريف | C9: ='بيانات المتدربين'!$J9 -> 2019/04/10 | D9: =DATEDIF(C9,TODAY(),"Y") -> 7 | E9: 125 | F9: =IF(D9>=15,E9*20%,IF(D9>=10,E9*15%,IF(D9>=5,E9*10%))) -> 12.5 | G9: =SUM(E9+F9) -> 137.5 | H9: S | I9: =IF(H9="M",F9*12%,IF(H9="S",F9*4%,IF(H9="R",F9*2%)))+G9 -> 138 | J9: =IF(OR(E9>100,D9>15),"متقاعد","قيد العمل") -> متقاعد
A10: =Table4[[#This Row],[الكود الوظيفي]] -> 3013 | B10: ='بيانات المتدربين'!$E10 -> جنى راشد العطار | C10: ='بيانات المتدربين'!$J10 -> 2013/09/20 | D10: =DATEDIF(C10,TODAY(),"Y") -> 12 | E10: 250 | F10: =IF(D10>=5,E10*5%,"ما عنا زيادة") -> 12.5 | G10: =SUM(E10+F10) -> 262.5 | H10: M | I10: =IF(H10="M",F10*12%,IF(H10="S",F10*4%,IF(H10="R",F10*2%)))+G10 -> 264 | J10: =IF(OR(E10>100,D10>15),"متقاعد","قيد العمل") -> متقاعد
A11: =Table4[[#This Row],[الكود الوظيفي]] -> 2013 | B11: ='بيانات المتدربين'!$E11 -> حمزة عياش المحمد | C11: ='بيانات المتدربين'!$J11 -> 2014/07/20 | D11: =DATEDIF(C11,TODAY(),"Y") -> 11 | E11: 140 | F11: =IF(D11>=5,E11*5%,"ما عنا زيادة") -> 7 | G11: =SUM(E11+F11) -> 147 | H11: S | I11: =IF(H11="M",F11*12%,IF(H11="S",F11*4%,IF(H11="R",F11*2%)))+G11 -> 147.28 | J11: =IF(OR(E11>100,D11>15),"متقاعد","قيد العمل") -> متقاعد
A12: =Table4[[#This Row],[الكود الوظيفي]] -> 1002 | B12: ='بيانات المتدربين'!$E12 -> خالد عمر المصري | C12: ='بيانات المتدربين'!$J12 -> 2009/01/25 | D12: =DATEDIF(C12,TODAY(),"Y") -> 17 | E12: 120 | F12: =IF(D12>=5,E12*5%,"ما عنا زيادة") -> 6 | G12: =SUM(E12+F12) -> 126 | H12: M | I12: =IF(H12="M",F12*12%,IF(H12="S",F12*4%,IF(H12="R",F12*2%)))+G12 -> 126.72 | J12: =IF(OR(E12>100,D12>15),"متقاعد","قيد العمل") -> متقاعد
A13: =Table4[[#This Row],[الكود الوظيفي]] -> 3018 | B13: ='بيانات المتدربين'!$E13 -> خلود صائب بكر | C13: ='بيانات المتدربين'!$J13 -> 2017/11/10 | D13: =DATEDIF(C13,TODAY(),"Y") -> 8 | E13: 300 | F13: =IF(D13>=5,E13*5%,"ما عنا زيادة") -> 15 | G13: =SUM(E13+F13) -> 315 | H13: R | I13: =IF(H13="M",F13*12%,IF(H13="S",F13*4%,IF(H13="R",F13*2%)))+G13 -> 315.3 | J13: =IF(OR(E13>100,D13>15),"متقاعد","قيد العمل") -> متقاعد
A14: =Table4[[#This Row],[الكود الوظيفي]] -> 4019 | B14: ='بيانات المتدربين'!$E14 -> دينا نبيل بركات | C14: ='بيانات المتدربين'!$J14 -> 2019/01/15 | D14: =DATEDIF(C14,TODAY(),"Y") -> 7 | E14: 123 | F14: =IF(D14>=5,E14*5%,"ما عنا زيادة") -> 6.15 | G14: =SUM(E14+F14) -> 129.15 | H14: R | I14: =IF(H14="M",F14*12%,IF(H14="S",F14*4%,IF(H14="R",F14*2%)))+G14 -> 129.273 | J14: =IF(OR(E14>100,D14>15),"متقاعد","قيد العمل") -> متقاعد
A15: =Table4[[#This Row],[الكود الوظيفي]] -> 4024 | B15: ='بيانات المتدربين'!$E15 -> رامي غياث طعمة | C15: ='بيانات المتدربين'!$J15 -> 2018/03/30 | D15: =DATEDIF(C15,TODAY(),"Y") -> 8 | E15: 145 | F15: =IF(D15>=5,E15*5%,"ما عنا زيادة") -> 7.25 | G15: =SUM(E15+F15) -> 152.25 | H15: R | I15: =IF(H15="M",F15*12%,IF(H15="S",F15*4%,IF(H15="R",F15*2%)))+G15 -> 152.395 | J15: =IF(OR(E15>100,D15>15),"متقاعد","قيد العمل") -> متقاعد
A16: =Table4[[#This Row],[الكود الوظيفي]] -> 4017 | B16: ='بيانات المتدربين'!$E16 -> رشا عبد الله صقر | C16: ='بيانات المتدربين'!$J16 -> 2019/06/25 | D16: =DATEDIF(C16,TODAY(),"Y") -> 6
A17: =Table4[[#This Row],[الكود الوظيفي]] -> 4018 | B17: ='بيانات المتدربين'!$E17 -> رغد عدنان حمد | C17: ='بيانات المتدربين'!$J17 -> 2017/08/20 | D17: =DATEDIF(C17,TODAY(),"Y") -> 8
A18: =Table4[[#This Row],[الكود الوظيفي]] -> 3012 | B18: ='بيانات المتدربين'!$E18 -> زياد مطيع العبود | C18: ='بيانات المتدربين'!$J18 -> 2016/10/18 | D18: =DATEDIF(C18,TODAY(),"Y") -> 9
A19: =Table4[[#This Row],[الكود الوظيفي]] -> 3010 | B19: ='بيانات المتدربين'!$E19 -> سامر وليد الخطيب | C19: ='بيانات المتدربين'!$J19 -> 2015/03/15 | D19: =DATEDIF(C19,TODAY(),"Y") -> 11
A20: =Table4[[#This Row],[الكود الوظيفي]] -> 2009 | B20: ='بيانات المتدربين'!$E20 -> سحر ماجد القاضي | C20: ='بيانات المتدربين'!$J20 -> 2013/05/10 | D20: =DATEDIF(C20,TODAY(),"Y") -> 12
A21: =Table4[[#This Row],[الكود الوظيفي]] -> 2010 | B21: ='بيانات المتدربين'!$E21 -> سلمى بشار الحكيم | C21: ='بيانات المتدربين'!$J21 -> 2011/02/28 | D21: =DATEDIF(C21,TODAY(),"Y") -> 15
A22: =Table4[[#This Row],[الكود الوظيفي]] -> 1011 | B22: ='بيانات المتدربين'!$E22 -> سلوى ممدوح السيد | C22: ='بيانات المتدربين'!$J22 -> 2011/08/10 | D22: =DATEDIF(C22,TODAY(),"Y") -> 14
A23: =Table4[[#This Row],[الكود الوظيفي]] -> 3012 | B23: ='بيانات المتدربين'!$E23 -> صفاء عصمت الرفاعي | C23: ='بيانات المتدربين'!$J23 -> 2017/06/14 | D23: =DATEDIF(C23,TODAY(),"Y") -> 8
A24: =Table4[[#This Row],[الكود الوظيفي]] -> 1004 | B24: ='بيانات المتدربين'!$E24 -> طارق منير الخوري | C24: ='بيانات المتدربين'!$J24 -> 2008/03/12 | D24: =DATEDIF(C24,TODAY(),"Y") -> 18
A25: =Table4[[#This Row],[الكود الوظيفي]] -> 4022 | B25: ='بيانات المتدربين'!$E25 -> طلال أسامة فوزي | C25: ='بيانات المتدربين'!$J25 -> 2018/08/14 | D25: =DATEDIF(C25,TODAY(),"Y") -> 7
A26: =Table4[[#This Row],[الكود الوظيفي]] -> 4020 | B26: ='بيانات المتدربين'!$E26 -> عبير سيف الدين | C26: ='بيانات المتدربين'!$J26 -> 2017/12/01 | D26: =DATEDIF(C26,TODAY(),"Y") -> 8
A27: =Table4[[#This Row],[الكود الوظيفي]] -> 1013 | B27: ='بيانات المتدربين'!$E27 -> عزة خيري بيك | C27: ='بيانات المتدربين'!$J27 -> 2008/09/05 | D27: =DATEDIF(C27,TODAY(),"Y") -> 17
... A51: =Table4[[#This Row],[الكود الوظيفي]] -> 2017 | B51: ='بيانات المتدربين'!$E51 -> يمان ظهير الحسن | C51: ='بيانات المتدربين'!$J51 -> 2012/05/12 | D51: =DATEDIF(C51,TODAY(),"Y") -> 13

Sheet المعاملات الوصفية
A1: المعاملة | B1: تاريخ التسليم | C1: الوقت المتبقي (شهر/يوم) | D1: الحالة | E1: معالجة الأخطاء | F1: التسليم | G1: الحالة | H1: 2 | I1: 3 | J1: 4
A2: المعاملة 2 | B2: 46057 | C2: =IF(B2<=TODAY(),"انتهى وقت التسليم",DATEDIF(TODAY(),B2,"M") & " Monthe and " & DATEDIF(TODAY(),B2,"MD") & " Days") -> انتهى وقت التسليم | D2: =IF(B2>TODAY(),"جاري العمل","انتهى وقت التسليم") -> انتهى وقت التسليم | E2: =IF(AND(F2="غير",D2="انتهى وقت التسليم"),"العملية صحيحة","يرجى مراجعة عملية التسليم") -> العملية صحيحة | F2: غير | G2: {=_xlfn.IFS(AND(I2>5, H2>5), "تنبيه: ضغط في التسليم والمراجعة معاً!",I2>5, "أكثر من 5 للتسليم",H2>5, "أكثر من 5 للمراجعة",TRUE, "الوضع مستقر")} -> تنبيه: ضغط في التسليم والمراجعة معاً! | H2: قيد المعالجة | I2: فشل التسليم | J2: المراجعة
A3: المعاملة 3 | B3: 46423 | C3: =IF(B3<=TODAY(),"انتهى وقت التسليم",DATEDIF(TODAY(),B3,"M") & " Monthe and " & DATEDIF(TODAY(),B3,"MD") & " Days") -> 9 Monthe and 10 Days | D3: =IF(B3>TODAY(),"جاري العمل","انتهى وقت التسليم") -> جاري العمل | E3: =IF(AND(F3="تم",D3="جاري العمل"),"العملية صحيحة","يرجى مراجعة عملية التسليم") -> يرجى مراجعة عملية التسليم | F3: غير | G3: {=_xlfn.IFS(AND(I3>5, H3>5), "تنبيه: ضغط في التسليم والمراجعة معاً!",I3>5, "أكثر من 5 للتسليم",H3>5, "أكثر من 5 للمراجعة",TRUE, "الوضع مستقر")} -> الوضع مستقر | H3: =COUNTIF(D:D,"جاري العمل") -> 2 | I3: =COUNTIF(D:D,"انتهى وقت التسليم") -> 5 | J3: =COUNTIF(E:E,"يرجى مراجعة عملية التسليم") -> 6
A4: المعاملة 4 | B4: 46057 | C4: =IF(B4<=TODAY(),"انتهى وقت التسليم",DATEDIF(TODAY(),B4,"M") & " Monthe and " & DATEDIF(TODAY(),B4,"MD") & " Days") -> انتهى وقت التسليم | D4: =IF(B4>TODAY(),"جاري العمل","انتهى وقت التسليم") -> انتهى وقت التسليم | E4: =IF(AND(F4="تم",D4="جاري العمل"),"العملية صحيحة","يرجى مراجعة عملية التسليم") -> يرجى مراجعة عملية التسليم | F4: غير | G4: {=_xlfn.IFS(AND(I4>5, H4>5), "تنبيه: ضغط في التسليم والمراجعة معاً!",I4>5, "أكثر من 5 للتسليم",H4>5, "أكثر من 5 للمراجعة",TRUE, "الوضع مستقر")} -> الوضع مستقر
A5: المعاملة 5 | B5: 46057 | C5: =IF(B5<=TODAY(),"انتهى وقت التسليم",DATEDIF(TODAY(),B5,"M") & " Monthe and " & DATEDIF(TODAY(),B5,"MD") & " Days") -> انتهى وقت التسليم | D5: =IF(B5>TODAY(),"جاري العمل","انتهى وقت التسليم") -> انتهى وقت التسليم | E5: =IF(AND(F5="تم",D5="جاري العمل"),"العملية صحيحة","يرجى مراجعة عملية التسليم") -> يرجى مراجعة عملية التسليم | F5: غير | G5: {=_xlfn.IFS(AND(I5>5, H5>5), "تنبيه: ضغط في التسليم والمراجعة معاً!",I5>5, "أكثر من 5 للتسليم",H5>5, "أكثر من 5 للمراجعة",TRUE, "الوضع مستقر")} -> الوضع مستقر
A6: المعاملة 6 | B6: 46057 | C6: =IF(B6<=TODAY(),"انتهى وقت التسليم",DATEDIF(TODAY(),B6,"M") & " Monthe and " & DATEDIF(TODAY(),B6,"MD") & " Days") -> انتهى وقت التسليم | D6: =IF(B6>TODAY(),"جاري العمل","انتهى وقت التسليم") -> انتهى وقت التسليم | E6: =IF(AND(F6="تم",D6="جاري العمل"),"العملية صحيحة","يرجى مراجعة عملية التسليم") -> يرجى مراجعة عملية التسليم | F6: تم | G6: {=_xlfn.IFS(AND(I6>5, H6>5), "تنبيه: ضغط في التسليم والمراجعة معاً!",I6>5, "أكثر من 5 للتسليم",H6>5, "أكثر من 5 للمراجعة",TRUE, "الوضع مستقر")} -> الوضع مستقر
A7: المعاملة 7 | B7: 46271 | C7: =IF(B7<=TODAY(),"انتهى وقت التسليم",DATEDIF(TODAY(),B7,"M") & " Monthe and " & DATEDIF(TODAY(),B7,"MD") & " Days") -> 4 Monthe and 11 Days | D7: =IF(B7>TODAY(),"جاري العمل","انتهى وقت التسليم") -> جاري العمل | E7: =IF(AND(F7="تم",D7="جاري العمل"),"العملية صحيحة","يرجى مراجعة عملية التسليم") -> يرجى مراجعة عملية التسليم | F7: غير | G7: {=_xlfn.IFS(AND(I7>5, H7>5), "تنبيه: ضغط في التسليم والمراجعة معاً!",I7>5, "أكثر من 5 للتسليم",H7>5, "أكثر من 5 للمراجعة",TRUE, "الوضع مستقر")} -> الوضع مستقر
A8: المعاملة 8 | B8: 45907 | C8: =IF(B8<=TODAY(),"انتهى وقت التسليم",DATEDIF(TODAY(),B8,"M") & " Monthe and " & DATEDIF(TODAY(),B8,"MD") & " Days") -> انتهى وقت التسليم | D8: =IF(B8>TODAY(),"جاري العمل","انتهى وقت التسليم") -> انتهى وقت التسليم | E8: =IF(AND(F8="تم",D8="جاري العمل"),"العملية صحيحة","يرجى مراجعة عملية التسليم") -> يرجى مراجعة عملية التسليم | F8: غير | G8: {=_xlfn.IFS(AND(I8>5, H8>5), "تنبيه: ضغط في التسليم والمراجعة معاً!",I8>5, "أكثر من 5 للتسليم",H8>5, "أكثر من 5 للمراجعة",TRUE, "الوضع مستقر")} -> الوضع مستقر

Sheet IFS
A1: الحالة | B1: التحويل | C1: التسليم | D1: النتيجة
A2: معالجة | D2: {=_xlfn.IFS(AND(A2="معالجة",B2="",C2=""),"انتظار",AND(A2="معالجة",B2="تم",C2="تم"),"نجاح",AND(A2="معالجة",B2="تم",C2=""),"لم يتم التسليم بعد")} -> انتظار
A3: معالجة | B3: تم | D3: {=_xlfn.IFS(AND(A3="معالجة",B3="",C3=""),"انتظار",AND(A3="معالجة",B3="تم",C3="تم"),"نجاح",AND(A3="معالجة",B3="تم",C3=""),"لم يتم التسليم بعد")} -> لم يتم التسليم بعد
A4: معالجة | B4: تم | C4: تم | D4: {=_xlfn.IFS(AND(A4="معالجة",B4="",C4=""),"انتظار",AND(A4="معالجة",B4="تم",C4="تم"),"نجاح",AND(A4="معالجة",B4="تم",C4=""),"لم يتم التسليم بعد")} -> نجاح
A5: معالجة | C5: تم | D5: {=_xlfn.IFS(AND(A5="معالجة",B5="",C5=""),"انتظار",AND(A5="معالجة",B5="تم",C5="تم"),"نجاح",AND(A5="معالجة",B5="تم",C5=""),"لم يتم التسليم بعد")} -> #N/A

Sheet الإحصاء
A1: عنوان الإحصاء | B1: العدد
A2: الموطفين | B2: =COUNTIF(Table4[تنظيف البيانات],"<>") -> 50 | C2: COUNTIF(RANGE,"<>")
A3: الذكور | B3: =COUNTIF('بيانات المتدربين'!F:F,"ذكر") -> 26 | C3: COUNTIF(RANGE,"ذكر")
A4: الإناث | B4: =COUNTIF('بيانات المتدربين'!F:F,"أنثى") -> 24 | C4: COUNTIF(RANGE,"أنثى")
A5: قسم HR | B5: =COUNTIF('بيانات المتدربين'!H:H,"HR") -> 9 | C5: COUNTIF(RANGE,"HR")
A6: قسم FIN | B6: =COUNTIF('بيانات المتدربين'!H:H,"FIN") -> 14 | C6: COUNTIF(RANGE,"FIN")
A7: قسم ADM | B7: =COUNTIF('بيانات المتدربين'!H:H,"ADM") -> 16 | C7: COUNTIF(RANGE,"ADM")
A8: قسم LEG | B8: =COUNTIF('بيانات المتدربين'!H:H,"LEG") -> 11 | C8: COUNTIF(RANGE,"LEG")
A9: > 2014 | B9: =COUNTIF('بيانات المتدربين'!I:I,">=2014") -> 22 | C9: COUNTIF(RANGE,">2014")
A10: < 2014 | B10: =COUNTIF('بيانات المتدربين'!I:I,"<2014") -> 28 | C10: COUNTIF(RANGE,"<2014")
A12: مجموعة الرواتب | B12: =SUMIF('المعاملات المالية'!H:J,الإحصاء!C12,'المعاملات المالية'!I:I) -> 610.64 | C12: S
A13: أعلى راتب | B13: 650
A14: أقل راتب | B14: =MIN('المعاملات المالية'!G:G) -> 99
A15: متوسط الرواتب | B15: =AVERAGE('المعاملات المالية'!G:G) -> 159.81429
